<?xml version="1.0"?>
<robot name="simrobot">
    <material name="black">
        <color rgba="0 0 0 1"/>
    </material>
    <material name="white">
        <color rgba="1 1 1 1"/>
    </material>
    <material name="blue">
        <color rgba="0.0 0.0 0.8 1.0"/>
    </material>

    <link name="base_footprint"/>

    <link name="base_link">
        <visual>
            <origin xyz="0 0 0" rpy="0 0 0"/>
            <geometry>
                <mesh filename="package://my_simrobot/meshes/base_link.STL"/>
            </geometry>
            <material name="black"/>
        </visual>
        <inertial>
            <origin xyz="-0.036932 -3.6183E-09 5.4279E-05" rpy="0 0 0"/>
            <mass value="0.62461"/>
            <inertia ixx="0.002014" ixy="3.2092E-10" ixz="-5.0446E-05" iyy="0.0023871" iyz="5.0493E-08" izz="0.0027336"/>
        </inertial>
        <collision>
            <origin xyz="0 0 0" rpy="0 0 0"/>
            <geometry>
                <mesh filename="package://my_simrobot/meshes/base_link.STL"/>
            </geometry>
        </collision>
    </link>
    <joint name="bash_link_joint" type="fixed">
        <axis rpy="0 0 0" xyz="0 0 0"/>
        <origin rpy="0 0 0" xyz="0 0 0"/>
        <parent link="base_footprint"/>
        <child link="base_link"/>
    </joint>

    <link name="right_wheel">
        <visual>
            <origin xyz="0 0 0" rpy="0 0 0"/>
            <geometry>
                <mesh filename="package://my_simrobot/meshes/right_wheel.STL"/>
            </geometry>
            <material name="white"/>
        </visual>
        <inertial>
            <origin xyz="0 -0.0033767 0" rpy="0 0 0"/>
            <mass value="0.052928"/>
            <inertia ixx="2.1269E-05" ixy="-7.7807E-22" ixz="2.6095E-21" iyy="3.6821E-05" iyz="-1.6034E-21" izz="2.1269E-05"/>
        </inertial>
        <collision>
            <origin xyz="0 0 0" rpy="0 0 0"/>
            <geometry>
                <mesh filename="package://my_simrobot/meshes/right_wheel.STL"/>
            </geometry>
        </collision>
    </link>
    <joint name="right_wheel_joint" type="continuous">
        <axis xyz="0 1 0"/>
        <origin rpy="-7.0774E-16 -6.9389E-18 9.8142E-17" xyz="0 -0.0775 -0.024"/>
        <limit effort="0.5" velocity="100"/>
        <dynamics damping="0.0" friction="0.5"/>
        <parent link="base_link"/>
        <child link="right_wheel"/>
    </joint>

    <link name="left_wheel">
        <visual>
            <origin xyz="0 0 0" rpy="0 0 0"/>
            <geometry>
                <mesh filename="package://my_simrobot/meshes/left_wheel.STL"/>
            </geometry>
            <material name="white"/>
        </visual>
        <inertial>
            <origin xyz="0 0.0033767 0" rpy="0 0 0"/>
            <mass value="0.052928"/>
            <inertia ixx="2.1269E-05" ixy="-8.5384E-22" ixz="-1.5763E-21" iyy="3.6821E-05" iyz="1.4005E-21" izz="2.1269E-05"/>
        </inertial>
        <collision>
            <origin xyz="0 0 0" rpy="0 0 0"/>
            <geometry>
                <mesh filename="package://my_simrobot/meshes/left_wheel.STL"/>
            </geometry>
        </collision>
    </link>
    <joint name="left_wheel_joint" type="continuous">
        <axis xyz="0 1 0"/>
        <origin rpy="-7.0774E-16 -6.9389E-18 9.8142E-17" xyz="0 0.0775 -0.024"/>
        <limit effort="0.5" velocity="100"/>
        <dynamics damping="0.0" friction="0.5"/>
        <parent link="base_link"/>
        <child link="left_wheel"/>
    </joint>    

    <link name="rplidar">
        <inertial>
            <mass value="1e-5"/>
            <origin rpy="0 0 0" xyz="0 0 0"/>
            <inertia ixx="1e-6" ixy="0" ixz="0" iyy="1e-6" iyz="0" izz="1e-6"/>
        </inertial>
        <visual>
            <origin rpy="0 0 0" xyz="0 0 0"/>
            <geometry>
                <mesh filename="package://my_simrobot/meshes/rplidar.dae"/>
            </geometry>
            <material name="blue"/>
        </visual>
        <collision>
            <origin rpy="0 0 0" xyz="0 0 0"/>
            <geometry>
                <mesh filename="package://my_simrobot/meshes/rplidar.dae"/> 
            </geometry>
        </collision>
    </link>
    <joint name="rplidar_joint" type="fixed">
        <axis xyz="0 1 0"/>
        <origin xyz="0 0 0.07"/>
        <parent link="base_link"/>
        <child link="rplidar"/>
    </joint>

</robot>