<?xml version="1.0"?>
<robot
  name="car4wd">
  <link name="base_footprint"/>
  <link
    name="base_link">
    <inertial>
      <origin
        xyz="-0.00133489696806633 -0.000858065236190794 0.0742947770696504"
        rpy="0 0 0" />
      <mass
        value="16.922536366276" />
      <inertia
        ixx="0.280375488027476"
        ixy="-3.3746922545933E-05"
        ixz="0.00723948806637425"
        iyy="0.376422394252491"
        iyz="-0.00156225089406068"
        izz="0.379035593736401" />
    </inertial>
    <visual>
      <origin
        xyz="0 0 0"
        rpy="0 0 0" />
      <geometry>
        <mesh
          filename="package://car4wd/meshes/base_link.STL" />
      </geometry>
      <material
        name="">
        <color
          rgba="0.752941176470588 0.752941176470588 0.752941176470588 1" />
      </material>
    </visual>
    <collision>
      <origin
        xyz="0 0 0"
        rpy="0 0 0" />
      <geometry>
        <mesh
          filename="package://car4wd/meshes/base_link.STL" />
      </geometry>
    </collision>
  </link>
    <joint name="bash_link_joint" type="fixed">
        <axis rpy="0 0 0" xyz="0 0 0"/>
        <origin rpy="0 0 0" xyz="0 0 0"/>
        <parent link="base_footprint"/>
        <child link="base_link"/>
    </joint>
  <link
    name="1_Link">
    <inertial>
      <origin
        xyz="-0 0 0"
        rpy="0 0 0" />
      <mass
        value="2.61977729811143" />
      <inertia
        ixx="0"
        ixy="0"
        ixz="0"
        iyy="0"
        iyz="0"
        izz="0" />
    </inertial>
    <visual>
      <origin
        xyz="0 0 0"
        rpy="0 0 0" />
      <geometry>
        <mesh
          filename="package://car4wd/meshes/1_Link.STL" />
      </geometry>
      <material
        name="">
        <color
          rgba="0.898039215686275 0.917647058823529 0.929411764705882 1" />
      </material>
    </visual>
    <collision>
      <origin
        xyz="0 0 0"
        rpy="0 0 0" />
      <geometry>
        <mesh
          filename="package://car4wd/meshes/1_Link.STL" />
      </geometry>
    </collision>
  </link>
  <joint
    name="1"
    type="continuous">
    <origin
      xyz="-0.18 -0.152 0"
      rpy="0 1.5707963267949 3.14" />
    <parent
      link="base_link" />
    <child
      link="1_Link" />
    <axis
      xyz="0 -1 0" />
  </joint>
  <link
    name="2_Link">
    <inertial>
      <origin
        xyz="0 0 0"
        rpy="0 0 0" />
      <mass
        value="2.61977729811143" />
      <inertia
        ixx="0"
        ixy="0"
        ixz="0"
        iyy="0"
        iyz="0"
        izz="0" />
    </inertial>
    <visual>
      <origin
        xyz="0 0 0"
        rpy="0 0 0" />
      <geometry>
        <mesh
          filename="package://car4wd/meshes/2_Link.STL" />
      </geometry>
      <material
        name="">
        <color
          rgba="0.898039215686275 0.917647058823529 0.929411764705882 1" />
      </material>
    </visual>
    <collision>
      <origin
        xyz="0 0 0"
        rpy="0 0 0" />
      <geometry>
        <mesh
          filename="package://car4wd/meshes/2_Link.STL" />
      </geometry>
    </collision>
  </link>
  <joint
    name="2"
    type="continuous">
    <origin
      xyz="0.18 -0.152 0"
      rpy="3.14159265358979 1.5707963267949 0" />
    <parent
      link="base_link" />
    <child
      link="2_Link" />
    <axis
      xyz="0 -1 0" />
  </joint>
  <link
    name="3_Link">
    <inertial>
      <origin
        xyz="0 0 0"
        rpy="0 0 0" />
      <mass
        value="2.61977729811143" />
      <inertia
        ixx="0"
        ixy="0"
        ixz="0"
        iyy="0"
        iyz="0"
        izz="0" />
    </inertial>
    <visual>
      <origin
        xyz="0 0 0"
        rpy="0 0 0" />
      <geometry>
        <mesh
          filename="package://car4wd/meshes/3_Link.STL" />
      </geometry>
      <material
        name="">
        <color
          rgba="0.898039215686275 0.917647058823529 0.929411764705882 1" />
      </material>
    </visual>
    <collision>
      <origin
        xyz="0 0 0"
        rpy="0 0 0" />
      <geometry>
        <mesh
          filename="package://car4wd/meshes/3_Link.STL" />
      </geometry>
    </collision>
  </link>
  <joint
    name="3"
    type="continuous">
    <origin
      xyz="0.18 0.152 0"
      rpy="2.69705607354159E-16 -0.0054048692832654 -2.9284720911018E-15" />
    <parent
      link="base_link" />
    <child
      link="3_Link" />
    <axis
      xyz="0 1 0" />
  </joint>
  <link
    name="4_Link">
    <inertial>
      <origin
        xyz="0 0 0"
        rpy="0 0 0" />
      <mass
        value="2.61977729811143" />
      <inertia
        ixx="0"
        ixy="0"
        ixz="0"
        iyy="0"
        iyz="0"
        izz="0" />
    </inertial>
    <visual>
      <origin
        xyz="0 0 0"
        rpy="0 0 0" />
      <geometry>
        <mesh
          filename="package://car4wd/meshes/4_Link.STL" />
      </geometry>
      <material
        name="">
        <color
          rgba="0.898039215686275 0.917647058823529 0.929411764705882 1" />
      </material>
    </visual>
    <collision>
      <origin
        xyz="0 0 0"
        rpy="0 0 0" />
      <geometry>
        <mesh
          filename="package://car4wd/meshes/4_Link.STL" />
      </geometry>
    </collision>
  </link>
  <joint
    name="4"
    type="continuous">
    <origin
      xyz="-0.18 0.152 0"
      rpy="-3.14159265358974 1.5098214433719 -3.14159265358974" />
    <parent
      link="base_link" />
    <child
      link="4_Link" />
    <axis
      xyz="0 1 0" />
  </joint>
  <link
    name="laser_Link">
    <inertial>
      <origin
        xyz="-0.000209603421815946 0.000120725292981872 -0.00801987647485995"
        rpy="0 0 0" />
      <mass
        value="0.271699065752244" />
      <inertia
        ixx="0"
        ixy="0"
        ixz="0"
        iyy="0"
        iyz="0"
        izz="0" />
    </inertial>
    <visual>
      <origin
        xyz="0 0 0"
        rpy="0 0 0" />
      <geometry>
        <mesh
          filename="package://car4wd/meshes/laser_Link.STL" />
      </geometry>
      <material
        name="">
        <color
          rgba="0.0588235294117647 0.00784313725490196 0 1" />
      </material>
    </visual>
    <collision>
      <origin
        xyz="0 0 0"
        rpy="0 0 0" />
      <geometry>
        <mesh
          filename="package://car4wd/meshes/laser_Link.STL" />
      </geometry>
    </collision>
  </link>
  <joint
    name="laser"
    type="fixed">
    <origin
      xyz="0.228 0 0.105"
      rpy="0 0 0" />
    <parent
      link="base_link" />
    <child
      link="laser_Link" />
    <axis
      xyz="0 0 0" />
  </joint>
<link name="rplidar">
        <inertial>
            <mass value="1e-5"/>
            <origin rpy="0 0 0" xyz="0 0 0"/>
            <inertia ixx="1e-6" ixy="0" ixz="0" iyy="1e-6" iyz="0" izz="1e-6"/>
        </inertial>
        <visual>
            <origin rpy="0 0 0" xyz="0 0 0"/>
            <geometry>
                <mesh filename="package://car4wd/meshes/rplidar.dae"/>
            </geometry>
            <material name="blue"/>
        </visual>
        <collision>
            <origin rpy="0 0 0" xyz="0 0 0"/>
            <geometry>
                <mesh filename="package://car4wd/meshes/rplidar.dae"/> 
            </geometry>
        </collision>
    </link>
    <joint name="rplidar_joint" type="fixed">
        <axis xyz="0 1 0"/>
        <origin xyz="0.228 0.0 0.225"/>
        <parent link="base_link"/>
        <child link="rplidar"/>
    </joint>

 <joint name="base_to_camera_joint" type="fixed">
            <parent link="base_link"/>
            <child link="usb_camera_link"/>
            <origin xyz="0.1 0.2 0.22" rpy="0 0 0" /> 
       </joint>

       <link name="usb_camera_link">
            <inertial>
                <mass value="0.1" />
                <origin xyz="0 0 0" />
                <inertia ixx="0.01" ixy="0.0" ixz="0.0"
                         iyy="0.01" iyz="0.0"
                         izz="0.01" />
            </inertial>

            <visual>
                <origin xyz=" 0 0 0 " rpy="0 0 0" />
                <geometry>
                    <box size="0.01 0.04 0.04" />
                </geometry>
                <material name="Black"/>
            </visual>

            <collision>
                <origin xyz="0.0 0.0 0.0" rpy="0 0 0" />
                <geometry>
                    <box size="0.01 0.04 0.04" />
                </geometry>
            </collision>
        </link>
 <link name="left_sonar">
      <visual>
        <origin xyz="0 0 0" rpy="0 1.57 0"/>
        <geometry>
          <cylinder length="0.01" radius="0.01"/>
        </geometry>
      </visual>
      <collision>
        <origin xyz="0 0 0" rpy="0 0 0"/>
        <geometry>
          <cylinder length="0.01" radius="0.01"/>
        </geometry>
      </collision>
            <collision>
                <origin xyz="0.0 0.0 0.0" rpy="0 0 0" />
                <geometry>
                    <box size="0.01 0.04 0.04" />
                </geometry>
            </collision>
        </link>
 
    <joint name="left_sonar_joint" type="fixed">
        <origin xyz="0.28 0 0.16" rpy="0 0 0"/>
        <parent link="base_link"/>
        <child link="left_sonar"/>
    </joint>        

 <link
    name="Link0">
    <inertial>
      <origin
        xyz="-0.001129 -0.0011291 0.01627"
        rpy="0 0 0" />
      <mass
        value="0.56333" />
      <inertia
        ixx="0.0011675"
        ixy="-4.7974E-05"
        ixz="1.3554E-05"
        iyy="0.0011675"
        iyz="1.3555E-05"
        izz="0.0021663" />
    </inertial>
    <visual>
      <origin
        xyz="0 0 0"
        rpy="0 0 0" />
      <geometry>
        <mesh
          filename="package://car4wd/meshes/Link0.STL" />
      </geometry>
      <material
        name="">
        <color
          rgba="0.066 0.066 0.066 1" />
      </material>
    </visual>
    <collision>
      <origin
        xyz="0 0 0"
        rpy="0 0 0" />
      <geometry>
        <mesh
          filename="package://car4wd/meshes/Link0.STL" />
      </geometry>
    </collision>
  </link>
<joint
    name="joint0"
    type="fixed">
    <origin
      xyz="-0.08 0 0.19"
      rpy="0 0 0" />
    <parent
      link="base_link" />
    <child
      link="Link0" />
    <axis
      xyz="0 0 0" />
  </joint>
  <link
    name="Link1">
    <inertial>
      <origin
        xyz="-8.6106E-07 0.051658 0.0053845"
        rpy="0 0 0" />
      <mass
        value="1.5667" />
      <inertia
        ixx="0.0039893"
        ixy="7.7306E-08"
        ixz="-5.125E-08"
        iyy="0.0030665"
        iyz="-0.00016458"
        izz="0.003855" />
    </inertial>
    <visual>
      <origin
        xyz="0 0 0"
        rpy="0 0 0" />
      <geometry>
        <mesh
          filename="package://car4wd/meshes/Link1.STL" />
      </geometry>
      <material
        name="">
        <color
          rgba="0.9529 0.823 0.313 1" />
      </material>
    </visual>
    <collision>
      <origin
        xyz="0 0 0"
        rpy="0 0 0" />
      <geometry>
        <mesh
          filename="package://car4wd/meshes/Link1.STL" />
      </geometry>
    </collision>
  </link>
  <joint
    name="joint1"
    type="fixed">
    <origin
      xyz="0 0 0.0607"
      rpy="1.5708 0 0.50479" />
    <parent
      link="Link0" />
    <child
      link="Link1" />
    <axis
      xyz="0 0 0" />
  </joint>
  <link
    name="Link2">
    <inertial>
      <origin
        xyz="-5.5102E-09 0.054334 0.204"
        rpy="0 0 0" />
      <mass
        value="4.0222" />
      <inertia
        ixx="0.144"
        ixy="-7.9038E-09"
        ixz="-7.1756E-07"
        iyy="0.14175"
        iyz="-3.5278E-08"
        izz="0.009481" />
    </inertial>
    <visual>
      <origin
        xyz="0 0 0"
        rpy="0 0 0" />
      <geometry>
        <mesh
          filename="package://car4wd/meshes/Link2.STL" />
      </geometry>
      <material
        name="">
        <color
          rgba="0.9529 0.823 0.313 1" />
      </material>
    </visual>
    <collision>
      <origin
        xyz="0 0 0"
        rpy="0 0 0" />
      <geometry>
        <mesh
          filename="package://car4wd/meshes/Link2.STL" />
      </geometry>
    </collision>
  </link>
  <joint
    name="joint2"
    type="fixed">
    <origin
      xyz="0 0.061 0.0795"
      rpy="1.5708 0 -2.0143" />
    <parent
      link="Link1" />
    <child
      link="Link2" />
    <axis
      xyz="0 0 0" />
  </joint>
  <link
    name="Link3">
    <inertial>
      <origin
        xyz="1.1466E-06 0.019915 -0.69278"
        rpy="0 0 0" />
      <mass
        value="2.2398" />
      <inertia
        ixx="0.043212"
        ixy="-3.5377E-08"
        ixz="-4.156E-07"
        iyy="0.042985"
        iyz="-0.0022331"
        izz="0.0020858" />
    </inertial>
    <visual>
      <origin
        xyz="0 0 0"
        rpy="0 0 0" />
      <geometry>
        <mesh
          filename="package://car4wd/meshes/Link3.STL" />
      </geometry>
      <material
        name="">
        <color
          rgba="0.9529 0.823 0.313 1" />
      </material>
    </visual>
    <collision>
      <origin
        xyz="0 0 0"
        rpy="0 0 0" />
      <geometry>
        <mesh
          filename="package://car4wd/meshes/Link3.STL" />
      </geometry>
    </collision>
  </link>
  <joint
    name="joint3"
    type="fixed">
    <origin
      xyz="0.35613 -0.0795 0.76816"
      rpy="0 0.77976 0" />
    <parent
      link="Link2" />
    <child
      link="Link3" />
    <axis
      xyz="0 0 0" />
  </joint>
  <link
    name="Link4">
    <inertial>
      <origin
        xyz="4.6902E-07 0.0041877 -0.033733"
        rpy="0 0 0" />
      <mass
        value="0.46883" />
      <inertia
        ixx="0.00058204"
        ixy="-9.4123E-09"
        ixz="-5.7631E-10"
        iyy="0.00055621"
        iyz="3.0952E-05"
        izz="0.00038659" />
    </inertial>
    <visual>
      <origin
        xyz="0 0 0"
        rpy="0 0 0" />
      <geometry>
        <mesh
          filename="package://car4wd/meshes/Link4.STL" />
      </geometry>
      <material
        name="">
        <color
          rgba="0.9529 0.823 0.313 1" />
      </material>
    </visual>
    <collision>
      <origin
        xyz="0 0 0"
        rpy="0 0 0" />
      <geometry>
        <mesh
          filename="package://car4wd/meshes/Link4.STL" />
      </geometry>
    </collision>
  </link>
  <joint
    name="joint4"
    type="fixed">
    <origin
      xyz="-0.022445 -0.0835 -0.92034"
      rpy="-3.1416 -0.53531 3.1416" />
    <parent
      link="Link3" />
    <child
      link="Link4" />
    <axis
      xyz="0 0 0" />
  </joint>
  <link
    name="Link5">
    <inertial>
      <origin
        xyz="7.2432E-07 0.0041878 -0.033733"
        rpy="0 0 0" />
      <mass
        value="0.46884" />
      <inertia
        ixx="0.00058205"
        ixy="-1.2007E-08"
        ixz="-1.8329E-10"
        iyy="0.00055621"
        iyz="3.0955E-05"
        izz="0.00038659" />
    </inertial>
    <visual>
      <origin
        xyz="0 0 0"
        rpy="0 0 0" />
      <geometry>
        <mesh
          filename="package://car4wd/meshes/Link5.STL" />
      </geometry>
      <material
        name="">
        <color
          rgba="0.9529 0.823 0.313 1" />
      </material>
    </visual>
    <collision>
      <origin
        xyz="0 0 0"
        rpy="0 0 0" />
      <geometry>
        <mesh
          filename="package://car4wd/meshes/Link5.STL" />
      </geometry>
    </collision>
  </link>
  <joint
    name="joint5"
    type="fixed">
    <origin
      xyz="-0.040387 0.017461 0.0585"
      rpy="-1.5708 0 1.1627" />
    <parent
      link="Link4" />
    <child
      link="Link5" />
    <axis
      xyz="0 0 0" />
  </joint>
  <link
    name="Link6">
    <inertial>
      <origin
        xyz="6.9389E-18 0.010011 -2.7756E-17"
        rpy="0 0 0" />
      <mass
        value="0.043466" />
      <inertia
        ixx="1.6279E-05"
        ixy="6.7763E-21"
        ixz="-1.2705E-21"
        iyy="3.1588E-05"
        iyz="-7.6233E-21"
        izz="1.8238E-05" />
    </inertial>
    <visual>
      <origin
        xyz="0 0 0"
        rpy="0 0 0" />
      <geometry>
        <mesh
          filename="package://car4wd/meshes/Link6.STL" />
      </geometry>
      <material
        name="">
        <color
          rgba="0.827 0.827 0.827 1" />
      </material>
    </visual>
    <collision>
      <origin
        xyz="0 0 0"
        rpy="0 0 0" />
      <geometry>
        <mesh
          filename="package://car4wd/meshes/Link6.STL" />
      </geometry>
    </collision>
  </link>
  <joint
    name="joint6"
    type="fixed">
    <origin
      xyz="0 0 0.0165"
      rpy="1.5708 0 1.7252" />
    <parent
      link="Link5" />
    <child
      link="Link6" />
    <axis
      xyz="0 0 0" />
  </joint>
  <link
    name="Link_grip">
    <inertial>
      <origin
        xyz="0.00025657 1.1387E-05 0.072949"
        rpy="0 0 0" />
      <mass
        value="0.36205" />
      <inertia
        ixx="0.00059204"
        ixy="-6.3398E-08"
        ixz="3.1052E-06"
        iyy="0.0004994"
        iyz="-1.0655E-06"
        izz="0.00019612" />
    </inertial>
    <visual>
      <origin
        xyz="0 0 0"
        rpy="0 0 0" />
      <geometry>
        <mesh
          filename="package://car4wd/meshes/Link_grip.STL" />
      </geometry>
      <material
        name="">
        <color
          rgba="0.168 0.168 0.168 1" />
      </material>
    </visual>
    <collision>
      <origin
        xyz="0 0 0"
        rpy="0 0 0" />
      <geometry>
        <mesh
          filename="package://car4wd/meshes/Link_grip.STL" />
      </geometry>
    </collision>
  </link>
  <joint
    name="joint_grip"
    type="fixed">
    <origin
      xyz="0 0.0016 0"
      rpy="1.5708 -1.5708 0" />
    <parent
      link="Link6" />
    <child
      link="Link_grip" />
    <axis
      xyz="0 0 0" />
  </joint>
 

</robot>
