<?xml version="1.0"?>
<robot xmlns:xacro="http://www.ros.org.wiki/xacro">

<xacro:macro name="car">
  <link name="base_footprint"/>
  <link
    name="base_link">
    <inertial>
      <origin
        xyz="-0.00133489696806633 -0.000858065236190794 0.0742947770696504"
        rpy="0 0 0" />
      <mass
        value="16.922536366276" />
      <inertia
        ixx="0.280375488027476"
        ixy="-3.3746922545933E-05"
        ixz="0.00723948806637425"
        iyy="0.376422394252491"
        iyz="-0.00156225089406068"
        izz="0.379035593736401" />
    </inertial>
    <visual>
      <origin
        xyz="0 0 0"
        rpy="0 0 0" />
      <geometry>
        <mesh
          filename="package://car4wd/meshes/base_link.STL" />
      </geometry>
      <material
        name="">
        <color
          rgba="0.752941176470588 0.752941176470588 0.752941176470588 1" />
      </material>
    </visual>
    <collision>
      <origin
        xyz="0 0 0"
        rpy="0 0 0" />
      <geometry>
        <mesh
          filename="package://car4wd/meshes/base_link.STL" />
      </geometry>
    </collision>
  </link>
    <joint name="bash_link_joint" type="fixed">
        <axis rpy="0 0 0" xyz="0 0 0"/>
        <origin rpy="0 0 0" xyz="0 0 0"/>
        <parent link="base_footprint"/>
        <child link="base_link"/>
    </joint>
  <link
    name="1_Link">
    <inertial>
      <origin
        xyz="-0 0 0"
        rpy="0 0 0" />
      <mass
        value="2.61977729811143" />
      <inertia
        ixx="0"
        ixy="0"
        ixz="0"
        iyy="0"
        iyz="0"
        izz="0" />
    </inertial>
    <visual>
      <origin
        xyz="0 0 0"
        rpy="0 0 0" />
      <geometry>
        <mesh
          filename="package://car4wd/meshes/1_Link.STL" />
      </geometry>
      <material
        name="">
        <color
          rgba="0.898039215686275 0.917647058823529 0.929411764705882 1" />
      </material>
    </visual>
    <collision>
      <origin
        xyz="0 0 0"
        rpy="0 0 0" />
      <geometry>
        <mesh
          filename="package://car4wd/meshes/1_Link.STL" />
      </geometry>
    </collision>
  </link>
  <joint
    name="1"
    type="continuous">
    <origin
      xyz="-0.18 -0.152 0"
      rpy="0 1.5707963267949 3.14" />
    <parent
      link="base_link" />
    <child
      link="1_Link" />
    <axis
      xyz="0 -1 0" />
  </joint>
  <link
    name="2_Link">
    <inertial>
      <origin
        xyz="0 0 0"
        rpy="0 0 0" />
      <mass
        value="2.61977729811143" />
      <inertia
        ixx="0"
        ixy="0"
        ixz="0"
        iyy="0"
        iyz="0"
        izz="0" />
    </inertial>
    <visual>
      <origin
        xyz="0 0 0"
        rpy="0 0 0" />
      <geometry>
        <mesh
          filename="package://car4wd/meshes/2_Link.STL" />
      </geometry>
      <material
        name="">
        <color
          rgba="0.898039215686275 0.917647058823529 0.929411764705882 1" />
      </material>
    </visual>
    <collision>
      <origin
        xyz="0 0 0"
        rpy="0 0 0" />
      <geometry>
        <mesh
          filename="package://car4wd/meshes/2_Link.STL" />
      </geometry>
    </collision>
  </link>
  <joint
    name="2"
    type="continuous">
    <origin
      xyz="0.18 -0.152 0"
      rpy="3.14159265358979 1.5707963267949 0" />
    <parent
      link="base_link" />
    <child
      link="2_Link" />
    <axis
      xyz="0 -1 0" />
  </joint>
  <link
    name="3_Link">
    <inertial>
      <origin
        xyz="0 0 0"
        rpy="0 0 0" />
      <mass
        value="2.61977729811143" />
      <inertia
        ixx="0"
        ixy="0"
        ixz="0"
        iyy="0"
        iyz="0"
        izz="0" />
    </inertial>
    <visual>
      <origin
        xyz="0 0 0"
        rpy="0 0 0" />
      <geometry>
        <mesh
          filename="package://car4wd/meshes/3_Link.STL" />
      </geometry>
      <material
        name="">
        <color
          rgba="0.898039215686275 0.917647058823529 0.929411764705882 1" />
      </material>
    </visual>
    <collision>
      <origin
        xyz="0 0 0"
        rpy="0 0 0" />
      <geometry>
        <mesh
          filename="package://car4wd/meshes/3_Link.STL" />
      </geometry>
    </collision>
  </link>
  <joint
    name="3"
    type="continuous">
    <origin
      xyz="0.18 0.152 0"
      rpy="2.69705607354159E-16 -0.0054048692832654 -2.9284720911018E-15" />
    <parent
      link="base_link" />
    <child
      link="3_Link" />
    <axis
      xyz="0 1 0" />
  </joint>
  <link
    name="4_Link">
    <inertial>
      <origin
        xyz="0 0 0"
        rpy="0 0 0" />
      <mass
        value="2.61977729811143" />
      <inertia
        ixx="0"
        ixy="0"
        ixz="0"
        iyy="0"
        iyz="0"
        izz="0" />
    </inertial>
    <visual>
      <origin
        xyz="0 0 0"
        rpy="0 0 0" />
      <geometry>
        <mesh
          filename="package://car4wd/meshes/4_Link.STL" />
      </geometry>
      <material
        name="">
        <color
          rgba="0.898039215686275 0.917647058823529 0.929411764705882 1" />
      </material>
    </visual>
    <collision>
      <origin
        xyz="0 0 0"
        rpy="0 0 0" />
      <geometry>
        <mesh
          filename="package://car4wd/meshes/4_Link.STL" />
      </geometry>
    </collision>
  </link>
  <joint
    name="4"
    type="continuous">
    <origin
      xyz="-0.18 0.152 0"
      rpy="-3.14159265358974 1.5098214433719 -3.14159265358974" />
    <parent
      link="base_link" />
    <child
      link="4_Link" />
    <axis
      xyz="0 1 0" />
  </joint>
  <link
    name="laser_Link">
    <inertial>
      <origin
        xyz="-0.000209603421815946 0.000120725292981872 -0.00801987647485995"
        rpy="0 0 0" />
      <mass
        value="0.271699065752244" />
      <inertia
        ixx="0"
        ixy="0"
        ixz="0"
        iyy="0"
        iyz="0"
        izz="0" />
    </inertial>
    <visual>
      <origin
        xyz="0 0 0"
        rpy="0 0 0" />
      <geometry>
        <mesh
          filename="package://car4wd/meshes/laser_Link.STL" />
      </geometry>
      <material
        name="">
        <color
          rgba="0.0588235294117647 0.00784313725490196 0 1" />
      </material>
    </visual>
    <collision>
      <origin
        xyz="0 0 0"
        rpy="0 0 0" />
      <geometry>
        <mesh
          filename="package://car4wd/meshes/laser_Link.STL" />
      </geometry>
    </collision>
  </link>
  <joint
    name="laser"
    type="fixed">
    <origin
      xyz="0.228 0 0.105"
      rpy="0 0 0" />
    <parent
      link="base_link" />
    <child
      link="laser_Link" />
    <axis
      xyz="0 0 0" />
  </joint>
<link name="rplidar">
        <inertial>
            <mass value="1e-5"/>
            <origin rpy="0 0 0" xyz="0 0 0"/>
            <inertia ixx="1e-6" ixy="0" ixz="0" iyy="1e-6" iyz="0" izz="1e-6"/>
        </inertial>
        <visual>
            <origin rpy="0 0 0" xyz="0 0 0"/>
            <geometry>
                <mesh filename="package://car4wd/meshes/rplidar.dae"/>
            </geometry>
            <material name="blue"/>
        </visual>
        <collision>
            <origin rpy="0 0 0" xyz="0 0 0"/>
            <geometry>
                <mesh filename="package://car4wd/meshes/rplidar.dae"/> 
            </geometry>
        </collision>
    </link>
    <joint name="rplidar_joint" type="fixed">
        <axis xyz="0 1 0"/>
        <origin xyz="0.228 0.0 0.225"/>
        <parent link="base_link"/>
        <child link="rplidar"/>
    </joint>

 <joint name="base_to_camera_joint" type="fixed">
            <parent link="base_link"/>
            <child link="usb_camera_link"/>
            <origin xyz="0.1 0.2 0.22" rpy="0 0 0" /> 
       </joint>

       <link name="usb_camera_link">
            <inertial>
                <mass value="0.1" />
                <origin xyz="0 0 0" />
                <inertia ixx="0.01" ixy="0.0" ixz="0.0"
                         iyy="0.01" iyz="0.0"
                         izz="0.01" />
            </inertial>

            <visual>
                <origin xyz=" 0 0 0 " rpy="0 0 0" />
                <geometry>
                    <box size="0.01 0.04 0.04" />
                </geometry>
                <material name="Black"/>
            </visual>

            <collision>
                <origin xyz="0.0 0.0 0.0" rpy="0 0 0" />
                <geometry>
                    <box size="0.01 0.04 0.04" />
                </geometry>
            </collision>
        </link>
 <link name="left_sonar">
      <visual>
        <origin xyz="0 0 0" rpy="0 1.57 0"/>
        <geometry>
          <cylinder length="0.01" radius="0.01"/>
        </geometry>
      </visual>
      <collision>
        <origin xyz="0 0 0" rpy="0 0 0"/>
        <geometry>
          <cylinder length="0.01" radius="0.01"/>
        </geometry>
      </collision>
            <collision>
                <origin xyz="0.0 0.0 0.0" rpy="0 0 0" />
                <geometry>
                    <box size="0.01 0.04 0.04" />
                </geometry>
            </collision>
        </link>
 
    <joint name="left_sonar_joint" type="fixed">
        <origin xyz="0.28 0 0.16" rpy="0 0 0"/>
        <parent link="base_link"/>
        <child link="left_sonar"/>
    </joint>        

 </xacro:macro>  
  

</robot>
