<?xml version="1.0" encoding="utf-8"?>
<!-- This URDF was automatically created by SolidWorks to URDF Exporter! Originally created by Stephen Brawner (brawner@gmail.com) 
     Commit Version: 1.5.0-0-g9aa0fdb  Build Version: 1.5.7004.21443
     For more information, please see http://wiki.ros.org/sw_urdf_exporter -->
<robot
  name="robot_arm_4dof">
  <link
    name="base_link">
    <inertial>
      <origin
        xyz="-0.0015249 0 0.020206"
        rpy="0 0 0" />
      <mass
        value="0.18853" />
      <inertia
        ixx="0.00023778"
        ixy="6.0727E-20"
        ixz="2.0572E-22"
        iyy="0.00027035"
        iyz="1.097E-21"
        izz="0.00050254" />
    </inertial>
    <visual>
      <origin
        xyz="0 0 0"
        rpy="0 0 0" />
      <geometry>
        <mesh
          filename="package://robot_arm_4dof_description/meshes/base_link.STL" />
      </geometry>
      <material
        name="">
        <color
          rgba="1 1 1 1" />
      </material>
    </visual>
    <collision>
      <origin
        xyz="0 0 0"
        rpy="0 0 0" />
      <geometry>
        <mesh
          filename="package://robot_arm_4dof_description/meshes/base_link.STL" />
      </geometry>
    </collision>
  </link>
  <link
    name="link1">
    <inertial>
      <origin
        xyz="-0.0034892 3.5885E-19 0.00035061"
        rpy="0 0 0" />
      <mass
        value="0.095317" />
      <inertia
        ixx="3.0197E-05"
        ixy="4.7168E-22"
        ixz="-5.447E-10"
        iyy="3.3082E-05"
        iyz="-4.6669E-22"
        izz="5.8999E-05" />
    </inertial>
    <visual>
      <origin
        xyz="0 0 0"
        rpy="0 0 0" />
      <geometry>
        <mesh
          filename="package://robot_arm_4dof_description/meshes/link1.STL" />
      </geometry>
      <material
        name="">
        <color
          rgba="1 1 1 1" />
      </material>
    </visual>
    <collision>
      <origin
        xyz="0 0 0"
        rpy="0 0 0" />
      <geometry>
        <mesh
          filename="package://robot_arm_4dof_description/meshes/link1.STL" />
      </geometry>
    </collision>
  </link>
  <joint
    name="joint1"
    type="revolute">
    <origin
      xyz="0 0 0.049"
      rpy="0 0 3.14159" />
    <parent
      link="base_link" />
    <child
      link="link1" />
    <axis
      xyz="0 0 1" />
    <limit
      lower="-3.1416"
      upper="3.1416"
      effort="0"
      velocity="0" />
    <safety_controller
      soft_upper_limit="3.1416"
      soft_lower_limit="-3.1416"
      k_position="100"
      k_velocity="1" />
  </joint>
  <link
    name="link2">
    <inertial>
      <origin
        xyz="0.048692 0 0"
        rpy="0 0 0" />
      <mass
        value="0.022109" />
      <inertia
        ixx="6.0251E-06"
        ixy="-5.3281E-22"
        ixz="6.4735E-24"
        iyy="8.5872E-06"
        iyz="-5.2397E-22"
        izz="4.7496E-06" />
    </inertial>
    <visual>
      <origin
        xyz="0 0 0"
        rpy="0 0 0" />
      <geometry>
        <mesh
          filename="package://robot_arm_4dof_description/meshes/link2.STL" />
      </geometry>
      <material
        name="">
        <color
          rgba="1 1 1 1" />
      </material>
    </visual>
    <collision>
      <origin
        xyz="0 0 0"
        rpy="0 0 0" />
      <geometry>
        <mesh
          filename="package://robot_arm_4dof_description/meshes/link2.STL" />
      </geometry>
    </collision>
  </link>
  <joint
    name="joint2"
    type="revolute">
    <origin
      xyz="0 0 0.0175"
      rpy="1.5708 -1.5708 0" />
    <parent
      link="link1" />
    <child
      link="link2" />
    <axis
      xyz="0 0 1" />
    <limit
      lower="-3.1416"
      upper="3.1416"
      effort="0"
      velocity="0" />
    <safety_controller
      soft_upper_limit="0.7854"
      soft_lower_limit="-1.5708"
      k_position="100"
      k_velocity="1" />
  </joint>
  <link
    name="link3">
    <inertial>
      <origin
        xyz="0.0485 0 0"
        rpy="0 0 0" />
      <mass
        value="0.061115" />
      <inertia
        ixx="6.1399E-06"
        ixy="4.6601E-18"
        ixz="-4.2024E-23"
        iyy="1.2106E-05"
        iyz="-6.0861E-23"
        izz="1.1137E-05" />
    </inertial>
    <visual>
      <origin
        xyz="0 0 0"
        rpy="0 0 0" />
      <geometry>
        <mesh
          filename="package://robot_arm_4dof_description/meshes/link3.STL" />
      </geometry>
      <material
        name="">
        <color
          rgba="1 1 1 1" />
      </material>
    </visual>
    <collision>
      <origin
        xyz="0 0 0"
        rpy="0 0 0" />
      <geometry>
        <mesh
          filename="package://robot_arm_4dof_description/meshes/link3.STL" />
      </geometry>
    </collision>
  </link>
  <joint
    name="joint3"
    type="revolute">
    <origin
      xyz="0.099 0 0"
      rpy="0 0 0" />
    <parent
      link="link2" />
    <child
      link="link3" />
    <axis
      xyz="0 0 -1" />
    <limit
      lower="-3.1416"
      upper="3.1416"
      effort="0"
      velocity="0" />
    <safety_controller
      soft_upper_limit="2.3562"
      soft_lower_limit="-2.3562"
      k_position="100"
      k_velocity="1" />
  </joint>
  <link
    name="link4">
    <inertial>
      <origin
        xyz="0.015667 0 0"
        rpy="0 0 0" />
      <mass
        value="0.0066298" />
      <inertia
        ixx="2.3018E-06"
        ixy="2.0733E-22"
        ixz="1.1702E-21"
        iyy="3.1361E-06"
        iyz="4.5558E-22"
        izz="1.4386E-06" />
    </inertial>
    <visual>
      <origin
        xyz="0 0 0"
        rpy="0 0 0" />
      <geometry>
        <mesh
          filename="package://robot_arm_4dof_description/meshes/link4.STL" />
      </geometry>
      <material
        name="">
        <color
          rgba="1 1 1 1" />
      </material>
    </visual>
    <collision>
      <origin
        xyz="0 0 0"
        rpy="0 0 0" />
      <geometry>
        <mesh
          filename="package://robot_arm_4dof_description/meshes/link4.STL" />
      </geometry>
    </collision>
  </link>
  <joint
    name="joint4"
    type="revolute">
    <origin
      xyz="0.097 0 0"
      rpy="0 0 0" />
    <parent
      link="link3" />
    <child
      link="link4" />
    <axis
      xyz="0 0 1" />
    <limit
      lower="-3.1416"
      upper="3.1416"
      effort="0"
      velocity="0" />
    <safety_controller
      soft_upper_limit="2.3562"
      soft_lower_limit="-1.5708"
      k_position="100"
      k_velocity="1" />
  </joint>

  <link name="fake_end"/>
  <joint name="fake_joint" type="fixed">
    <origin xyz="0 0 0" rpy="0 0 0" />
    <parent link="link4" />
    <child link="fake_end" />
  </joint>
</robot>
